{"errorMessage": "An error occurred (NoSuchBucket) when calling the ListObjectsV2 operation: The specified bucket does not exist", "errorType": "NoSuchBucket", "requestId": "7f05a113-982d-4b9c-bc2a-9fd7ed98c017", "stackTrace": ["  File \"/var/task/fetch.py\", line 63, in lambda_handler\n    raise e\n", "  File \"/var/task/fetch.py\", line 29, in lambda_handler\n    objects = s3_client.list_objects_v2(Bucket=os.environ['WEBSITE_ASSETS_BUCKET'], Prefix='images/uploads')\n", "  File \"/var/lang/lib/python3.12/site-packages/botocore/client.py\", line 602, in _api_call\n    return self._make_api_call(operation_name, kwargs)\n", "  File \"/var/lang/lib/python3.12/site-packages/botocore/context.py\", line 123, in wrapper\n    return func(*args, **kwargs)\n", "  File \"/var/lang/lib/python3.12/site-packages/botocore/client.py\", line 1078, in _make_api_call\n    raise error_class(parsed_response, operation_name)\n"]}