{"errorMessage": "An error occurred (AccessDenied) when calling the ListObjectsV2 operation: User: arn:aws:sts::140324736937:assumed-role/fetch-images-role/fetch-image-function is not authorized to perform: s3:ListBucket on resource: \"arn:aws:s3:::140324736937-website-assets-us-east-1\" because no identity-based policy allows the s3:ListBucket action", "errorType": "ClientError", "requestId": "e7c39382-0921-4f61-b426-d5db91bfcba8", "stackTrace": ["  File \"/var/task/fetch.py\", line 63, in lambda_handler\n    raise e\n", "  File \"/var/task/fetch.py\", line 29, in lambda_handler\n    objects = s3_client.list_objects_v2(Bucket=os.environ['WEBSITE_ASSETS_BUCKET'], Prefix='images/uploads')\n", "  File \"/var/lang/lib/python3.12/site-packages/botocore/client.py\", line 602, in _api_call\n    return self._make_api_call(operation_name, kwargs)\n", "  File \"/var/lang/lib/python3.12/site-packages/botocore/context.py\", line 123, in wrapper\n    return func(*args, **kwargs)\n", "  File \"/var/lang/lib/python3.12/site-packages/botocore/client.py\", line 1078, in _make_api_call\n    raise error_class(parsed_response, operation_name)\n"]}